try:
    #forzamos excepci贸n
    x= 2/0
except:
    #Se entra ya que ha habido una excepci贸n
    print("Entra en except, ha ocurrido una excepci贸n")
finally:
    #Tambien entra porque finally es ejecutado siempre
    print("Entra en finally, se ejecuta el bloque finally")
    
#Entra en except, ha ocurrido una excepci贸n
#Entra en finally, se ejecuta el bloque finally